[28/Jul/2022 08:19:01] ERROR [django.request:118] Internal Server Error: /auth/
Traceback (most recent call last):
  File "C:\Python36\lib\site-packages\django\core\handlers\exception.py", line 35, in inner
    response = get_response(request)
  File "C:\Python36\lib\site-packages\django\core\handlers\base.py", line 128, in _get_response
    response = self.process_exception_by_middleware(e, request)
  File "C:\Python36\lib\site-packages\django\core\handlers\base.py", line 126, in _get_response
    response = wrapped_callback(request, *callback_args, **callback_kwargs)
TypeError: auth() missing 1 required positional argument: 'pid'
[28/Jul/2022 08:20:54] ERROR [django.request:118] Internal Server Error: /auth/12
Traceback (most recent call last):
  File "C:\Users\Ainur.fadzil\Documents\Developement\gatewaynum_py3\app\views.py", line 191, in auth
    return login_(req, render_to_string('app/_errorlist.html', { 'errorlist': le }))
  File "C:\Users\Ainur.fadzil\Documents\Developement\gatewaynum_py3\app\views.py", line 100, in login_
    return render(req, 'app/login.html', context=ctx)
  File "C:\Python36\lib\site-packages\django\shortcuts.py", line 36, in render
    content = loader.render_to_string(template_name, context, request, using=using)
  File "C:\Python36\lib\site-packages\django\template\loader.py", line 62, in render_to_string
    return template.render(context, request)
  File "C:\Python36\lib\site-packages\django\template\backends\django.py", line 61, in render
    return self.template.render(context)
  File "C:\Python36\lib\site-packages\django\template\base.py", line 175, in render
    return self._render(context)
  File "C:\Python36\lib\site-packages\django\template\base.py", line 167, in _render
    return self.nodelist.render(context)
  File "C:\Python36\lib\site-packages\django\template\base.py", line 943, in render
    bit = node.render_annotated(context)
  File "C:\Python36\lib\site-packages\django\template\base.py", line 910, in render_annotated
    return self.render(context)
  File "C:\Python36\lib\site-packages\django\template\loader_tags.py", line 155, in render
    return compiled_parent._render(context)
  File "C:\Python36\lib\site-packages\django\template\base.py", line 167, in _render
    return self.nodelist.render(context)
  File "C:\Python36\lib\site-packages\django\template\base.py", line 943, in render
    bit = node.render_annotated(context)
  File "C:\Python36\lib\site-packages\django\template\base.py", line 910, in render_annotated
    return self.render(context)
  File "C:\Python36\lib\site-packages\django\template\loader_tags.py", line 67, in render
    result = block.nodelist.render(context)
  File "C:\Python36\lib\site-packages\django\template\base.py", line 943, in render
    bit = node.render_annotated(context)
  File "C:\Python36\lib\site-packages\django\template\base.py", line 910, in render_annotated
    return self.render(context)
  File "C:\Python36\lib\site-packages\django\template\defaulttags.py", line 447, in render
    url = reverse(view_name, args=args, kwargs=kwargs, current_app=current_app)
  File "C:\Python36\lib\site-packages\django\urls\base.py", line 88, in reverse
    return iri_to_uri(resolver._reverse_with_prefix(view, prefix, *args, **kwargs))
  File "C:\Python36\lib\site-packages\django\urls\resolvers.py", line 632, in _reverse_with_prefix
    raise NoReverseMatch(msg)
django.urls.exceptions.NoReverseMatch: Reverse for 'auth' with no arguments not found. 1 pattern(s) tried: ['auth/(?P<pid>[0-9]+)$']

During handling of the above exception, another exception occurred:

Traceback (most recent call last):
  File "C:\Python36\lib\site-packages\django\core\handlers\exception.py", line 35, in inner
    response = get_response(request)
  File "C:\Python36\lib\site-packages\django\core\handlers\base.py", line 128, in _get_response
    response = self.process_exception_by_middleware(e, request)
  File "C:\Python36\lib\site-packages\django\core\handlers\base.py", line 126, in _get_response
    response = wrapped_callback(request, *callback_args, **callback_kwargs)
  File "C:\Users\Ainur.fadzil\Documents\Developement\gatewaynum_py3\app\views.py", line 210, in auth
    return login_(req, str(e))
  File "C:\Users\Ainur.fadzil\Documents\Developement\gatewaynum_py3\app\views.py", line 100, in login_
    return render(req, 'app/login.html', context=ctx)
  File "C:\Python36\lib\site-packages\django\shortcuts.py", line 36, in render
    content = loader.render_to_string(template_name, context, request, using=using)
  File "C:\Python36\lib\site-packages\django\template\loader.py", line 62, in render_to_string
    return template.render(context, request)
  File "C:\Python36\lib\site-packages\django\template\backends\django.py", line 61, in render
    return self.template.render(context)
  File "C:\Python36\lib\site-packages\django\template\base.py", line 175, in render
    return self._render(context)
  File "C:\Python36\lib\site-packages\django\template\base.py", line 167, in _render
    return self.nodelist.render(context)
  File "C:\Python36\lib\site-packages\django\template\base.py", line 943, in render
    bit = node.render_annotated(context)
  File "C:\Python36\lib\site-packages\django\template\base.py", line 910, in render_annotated
    return self.render(context)
  File "C:\Python36\lib\site-packages\django\template\loader_tags.py", line 155, in render
    return compiled_parent._render(context)
  File "C:\Python36\lib\site-packages\django\template\base.py", line 167, in _render
    return self.nodelist.render(context)
  File "C:\Python36\lib\site-packages\django\template\base.py", line 943, in render
    bit = node.render_annotated(context)
  File "C:\Python36\lib\site-packages\django\template\base.py", line 910, in render_annotated
    return self.render(context)
  File "C:\Python36\lib\site-packages\django\template\loader_tags.py", line 67, in render
    result = block.nodelist.render(context)
  File "C:\Python36\lib\site-packages\django\template\base.py", line 943, in render
    bit = node.render_annotated(context)
  File "C:\Python36\lib\site-packages\django\template\base.py", line 910, in render_annotated
    return self.render(context)
  File "C:\Python36\lib\site-packages\django\template\defaulttags.py", line 447, in render
    url = reverse(view_name, args=args, kwargs=kwargs, current_app=current_app)
  File "C:\Python36\lib\site-packages\django\urls\base.py", line 88, in reverse
    return iri_to_uri(resolver._reverse_with_prefix(view, prefix, *args, **kwargs))
  File "C:\Python36\lib\site-packages\django\urls\resolvers.py", line 632, in _reverse_with_prefix
    raise NoReverseMatch(msg)
django.urls.exceptions.NoReverseMatch: Reverse for 'auth' with no arguments not found. 1 pattern(s) tried: ['auth/(?P<pid>[0-9]+)$']
[28/Jul/2022 08:24:41] ERROR [django.request:118] Internal Server Error: /accounts/login/
Traceback (most recent call last):
  File "C:\Python36\lib\site-packages\django\core\handlers\exception.py", line 35, in inner
    response = get_response(request)
  File "C:\Python36\lib\site-packages\django\core\handlers\base.py", line 128, in _get_response
    response = self.process_exception_by_middleware(e, request)
  File "C:\Python36\lib\site-packages\django\core\handlers\base.py", line 126, in _get_response
    response = wrapped_callback(request, *callback_args, **callback_kwargs)
  File "C:\Users\Ainur.fadzil\Documents\Developement\gatewaynum_py3\app\views.py", line 62, in loginview
    return login_(req)
  File "C:\Users\Ainur.fadzil\Documents\Developement\gatewaynum_py3\app\views.py", line 100, in login_
    return render(req, 'app/login.html', context=ctx)
  File "C:\Python36\lib\site-packages\django\shortcuts.py", line 36, in render
    content = loader.render_to_string(template_name, context, request, using=using)
  File "C:\Python36\lib\site-packages\django\template\loader.py", line 62, in render_to_string
    return template.render(context, request)
  File "C:\Python36\lib\site-packages\django\template\backends\django.py", line 61, in render
    return self.template.render(context)
  File "C:\Python36\lib\site-packages\django\template\base.py", line 175, in render
    return self._render(context)
  File "C:\Python36\lib\site-packages\django\template\base.py", line 167, in _render
    return self.nodelist.render(context)
  File "C:\Python36\lib\site-packages\django\template\base.py", line 943, in render
    bit = node.render_annotated(context)
  File "C:\Python36\lib\site-packages\django\template\base.py", line 910, in render_annotated
    return self.render(context)
  File "C:\Python36\lib\site-packages\django\template\loader_tags.py", line 155, in render
    return compiled_parent._render(context)
  File "C:\Python36\lib\site-packages\django\template\base.py", line 167, in _render
    return self.nodelist.render(context)
  File "C:\Python36\lib\site-packages\django\template\base.py", line 943, in render
    bit = node.render_annotated(context)
  File "C:\Python36\lib\site-packages\django\template\base.py", line 910, in render_annotated
    return self.render(context)
  File "C:\Python36\lib\site-packages\django\template\loader_tags.py", line 67, in render
    result = block.nodelist.render(context)
  File "C:\Python36\lib\site-packages\django\template\base.py", line 943, in render
    bit = node.render_annotated(context)
  File "C:\Python36\lib\site-packages\django\template\base.py", line 910, in render_annotated
    return self.render(context)
  File "C:\Python36\lib\site-packages\django\template\defaulttags.py", line 447, in render
    url = reverse(view_name, args=args, kwargs=kwargs, current_app=current_app)
  File "C:\Python36\lib\site-packages\django\urls\base.py", line 88, in reverse
    return iri_to_uri(resolver._reverse_with_prefix(view, prefix, *args, **kwargs))
  File "C:\Python36\lib\site-packages\django\urls\resolvers.py", line 632, in _reverse_with_prefix
    raise NoReverseMatch(msg)
django.urls.exceptions.NoReverseMatch: Reverse for 'auth' not found. 'auth' is not a valid view function or pattern name.
[28/Jul/2022 08:24:58] ERROR [django.request:118] Internal Server Error: /auth/
Traceback (most recent call last):
  File "C:\Python36\lib\site-packages\django\core\handlers\exception.py", line 35, in inner
    response = get_response(request)
  File "C:\Python36\lib\site-packages\django\core\handlers\base.py", line 128, in _get_response
    response = self.process_exception_by_middleware(e, request)
  File "C:\Python36\lib\site-packages\django\core\handlers\base.py", line 126, in _get_response
    response = wrapped_callback(request, *callback_args, **callback_kwargs)
TypeError: auth() missing 1 required positional argument: 'pid'
[28/Jul/2022 08:30:07] ERROR [django.request:118] Internal Server Error: /app/cust/loginemail/nur
Traceback (most recent call last):
  File "C:\Python36\lib\site-packages\django\core\handlers\exception.py", line 35, in inner
    response = get_response(request)
  File "C:\Python36\lib\site-packages\django\utils\deprecation.py", line 97, in __call__
    response = self.process_response(request, response)
  File "C:\Python36\lib\site-packages\django\middleware\clickjacking.py", line 26, in process_response
    if response.get('X-Frame-Options') is not None:
AttributeError: 'str' object has no attribute 'get'
[28/Jul/2022 08:30:16] ERROR [django.request:118] Internal Server Error: /app/cust/loginemail/9302
Traceback (most recent call last):
  File "C:\Python36\lib\site-packages\django\core\handlers\exception.py", line 35, in inner
    response = get_response(request)
  File "C:\Python36\lib\site-packages\django\utils\deprecation.py", line 97, in __call__
    response = self.process_response(request, response)
  File "C:\Python36\lib\site-packages\django\middleware\clickjacking.py", line 26, in process_response
    if response.get('X-Frame-Options') is not None:
AttributeError: 'str' object has no attribute 'get'
[28/Jul/2022 08:33:45] ERROR [django.request:118] Internal Server Error: /app/cust/loginemail/9302
Traceback (most recent call last):
  File "C:\Python36\lib\site-packages\django\core\handlers\exception.py", line 35, in inner
    response = get_response(request)
  File "C:\Python36\lib\site-packages\django\utils\deprecation.py", line 97, in __call__
    response = self.process_response(request, response)
  File "C:\Python36\lib\site-packages\django\middleware\clickjacking.py", line 26, in process_response
    if response.get('X-Frame-Options') is not None:
AttributeError: 'str' object has no attribute 'get'
[28/Jul/2022 12:00:54] ERROR [django.request:118] Internal Server Error: /accounts/login/
Traceback (most recent call last):
  File "C:\Python36\lib\site-packages\django\core\handlers\exception.py", line 35, in inner
    response = get_response(request)
  File "C:\Python36\lib\site-packages\django\core\handlers\base.py", line 128, in _get_response
    response = self.process_exception_by_middleware(e, request)
  File "C:\Python36\lib\site-packages\django\core\handlers\base.py", line 126, in _get_response
    response = wrapped_callback(request, *callback_args, **callback_kwargs)
  File "C:\Users\Ainur.fadzil\Documents\Developement\gatewaynum_py3\app\views.py", line 63, in loginview
    return login_(req)
  File "C:\Users\Ainur.fadzil\Documents\Developement\gatewaynum_py3\app\views.py", line 102, in login_
    return render(req, 'app/login.html', context=ctx)
NameError: name 'ctx' is not defined
